{
	"xsize": 16,
	"zsize": 16,
	"Description": "",
	"palette": {
		"palette": [
			{
				"char": "2",
				"block": "buildersdelight:bricks_4",
				"Description": "Floor",
				"Color": "cdb23fff"
			},
			{
				"char": "3",
				"block": "chipped:dark_oak_planks_37",
				"Description": "Ceiling",
				"Color": "442b14ff"
			},
			{
				"char": "i",
				"block": "the_vault:living_rock_block_stacked",
				"Description": "Wall",
				"Color": "9e9e9eff"
			},
			{
				"char": "7",
				"block": "rechiseled:oak_planks_beams_connecting",
				"Description": "Ceiling Inlay",
				"Color": "867c52ff"
			},
			{
				"char": "U",
				"block": "luphieclutteredmod:luphie_wine_bottle_rack[facing=west]",
				"Description": "Wine Cabinet - West Facing",
				"Color": "c2b78fff"
			},
			{
				"char": "H",
				"block": "everycomp:fd/ecologics/coconut_cabinet[facing=west,open=false]",
				"Description": "Cabinet - West Facing",
				"Color": "c2b78fff"
			},
			{
				"char": "5",
				"block": "buildersdelight:brick_slab_4[type=bottom,waterlogged=false]",
				"Description": "",
				"Color": "ab9946ff"
			},
			{
				"char": "q",
				"block": "chipped:bookshelf_12",
				"Description": "Bottom Shelf - Empty",
				"Color": "8e8b7cff"
			},
			{
				"char": "o",
				"block": "everycomp:fd/ecologics/coconut_cabinet[facing=east,open=false]",
				"Description": "Cabinet - East Facing",
				"Color": "c2b78fff"
			},
			{
				"char": "O",
				"block": "lightmanscurrency:bookshelf_trader_oak[facing=east]",
				"Description": "Empty Shelf - East Facing",
				"Color": "c2b78fff"
			},
			{
				"char": "n",
				"block": "tanukidecor:antique_wall_shelf[facing=south,waterlogged=false]",
				"Description": "Alcove Shelf",
				"Color": "7e6f3dff"
			},
			{
				"char": "r",
				"block": "chipped:bookshelf_2",
				"Description": "Bottom Shelf - Filled",
				"Color": "99937fff"
			},
			{
				"char": "s",
				"block": "buildersdelight:brick_stairs_4[facing=south,half=bottom,shape=straight,waterlogged=false]",
				"Description": "Brick Stairs",
				"Color": "b9b05eff"
			},
			{
				"char": "P",
				"block": "luphieclutteredmod:luphie_wine_bottle_rack[facing=east]",
				"Description": "",
				"Color": "b9af5eff"
			},
			{
				"char": "0",
				"block": "moa_decor_art:lienzo[facing=north]",
				"Description": "Painting"
			},
			{
				"char": "V",
				"block": "lightmanscurrency:bookshelf_trader_oak[facing=west]",
				"Description": "Empty Shelf - West Facing",
				"Color": "c2b78fff"
			},
			{
				"char": "N",
				"block": "moa_decor_holidays:estrella_navidena[facing=south]",
				"Description": "Alcove Deco",
				"Color": "e8e53bff"
			}
		]
	},
	"slices": [
		[
			"X$#####$$#####$X",
			"$22222222222222$",
			"#22222222222222#",
			"#22222222222222#",
			"#22222222222222#",
			"#22222222222222#",
			"#22222222222222#",
			"$22222222222222$",
			"$22222222222222$",
			"#22222222222222#",
			"#22222222222222#",
			"#22222222222222#",
			"#22222222222222#",
			"#22222222222222#",
			"$22222222l22222$",
			"X$#####$$#####$X"
		],
		[
			"X#$##########$#X",
			"#iiiiiiiiiiiiii#",
			"$iiiiiiiiiiiiii$",
			"#iiiiiiiiiiiiii#",
			"#iiiiiiiiiiiiii#",
			"#iiiiiiiiiiiiii#",
			"#iiiiiiiiiiiiii#",
			"#iiiiiiiniiiiii#",
			"#iiiiio   qiiii#",
			"#iiiiir   qiiii#",
			"#iiiiiq   riiii#",
			"#iiiiiq   qiiii#",
			"#iiiiiisƚƚHiiii#",
			"$iiiiii2iiiiiii$",
			"#iiiiii2iliiiii#",
			"X#$##########$#X"
		],
		[
			"X##$########$##X",
			"#iiiiiiiiiiiiii#",
			"#iiiiiiiiiiiiii#",
			"$iiiiiiiiiiiiii$",
			"#iiiiiiiiiiiiii#",
			"#iiiiiiiiiiiiii#",
			"#iiiiiiiiiiiiii#",
			"#iiiiiiiNiiiiii#",
			"#iiiiio   Oiiii#",
			"#iiiiiP   Uiiii#",
			"#iiiiiP   Uiiii#",
			"#iiiiiV   Uiiii#",
			"$iiiiii  ▦Hiiii$",
			"#iiiiii iiiiiii#",
			"#iiiiii5 liiiii#",
			"X##$########$##X"
		],
		[
			"X###$######$###X",
			"#iiiiiiiiiiiiii#",
			"#iiiiiiiiiiiiii#",
			"#iiiiiiiiiiiiii#",
			"$iiiiiiiiiiiiii$",
			"#iiiiiiiiiiiiii#",
			"#iiiiiiiiiiiiii#",
			"#iiiiiiiiiiiiii#",
			"#iiiiio   Oiiii#",
			"#iiiiiP   Uiiii#",
			"#iiiiiP   Uiiii#",
			"$iiiiiV   Uiiii$",
			"#iiiiii ▦ Hiiii#",
			"#iiiiii iiiiiii#",
			"#iiiiii  liiiii#",
			"X###$######$###X"
		],
		[
			"X####$####$####X",
			"#iiiiiiiiiiiiii#",
			"#iiiii33733iiii#",
			"#iiiii33733iiii#",
			"#iiiii33733iiii#",
			"$iiiii33733iiii$",
			"#iiiii33733iiii#",
			"#iiiii33733iiii#",
			"#iiiii33733iiii#",
			"#iiiii33733iiii#",
			"$iiiii33733iiii$",
			"#iiiii33733iiii#",
			"#iiiiii3733iiii#",
			"#iiiiii iiiiiii#",
			"#iiiiii  liiiii#",
			"X####$####$####X"
		],
		[
			"X#####$##$#####X",
			"#33333333333333#",
			"#33333333333333#",
			"#33333333333333#",
			"#33333333333333#",
			"#33333333333333#",
			"$33333333333333$",
			"#33333333333333#",
			"#33333333333333#",
			"$33333333333333$",
			"#33333333333333#",
			"#33333333333333#",
			"#33333333333333#",
			"#33333333333333#",
			"#33333333l33333#",
			"X#####$##$#####X"
		]
	]
}