{
	"xsize": 16,
	"zsize": 16,
	"Description": "Shop - Ice Cream",
	"palette": {
		"palette": [
			{
				"char": "4",
				"block": "buildersdelight:glass_5",
				"Description": "Glass",
				"Color": "2422aaff"
			},
			{
				"char": "i",
				"block": "simplylight:edge_light_top[east=false,north=true,south=false,waterlogged=false,west=false]",
				"Description": ""
			},
			{
				"char": "m",
				"block": "simplylight:edge_light_top[east=true,north=false,south=false,waterlogged=false,west=false]",
				"Description": ""
			},
			{
				"char": "k",
				"block": "simplylight:edge_light_top[east=false,north=false,south=false,waterlogged=false,west=true]",
				"Description": ""
			},
			{
				"char": "j",
				"block": "simplylight:edge_light_top[east=true,north=true,south=false,waterlogged=false,west=false]",
				"Description": ""
			},
			{
				"char": "o",
				"block": "simplylight:edge_light_top[east=false,north=false,south=true,waterlogged=false,west=false]",
				"Description": ""
			},
			{
				"char": "n",
				"block": "simplylight:edge_light_top[east=false,north=false,south=true,waterlogged=false,west=true]",
				"Description": ""
			},
			{
				"char": "f",
				"block": "simplylight:edge_light_top[east=false,north=true,south=false,waterlogged=false,west=true]",
				"Description": ""
			},
			{
				"char": "q",
				"block": "simplylight:edge_light_top[east=true,north=false,south=true,waterlogged=false,west=false]",
				"Description": ""
			},
			{
				"char": "e",
				"block": "moa_decor_cookery:refrigerador[facing=south]",
				"Description": "Fridge - Style 1",
				"Color": "a5a5a5ff"
			},
			{
				"char": "3",
				"block": "cfm:fridge_light[facing=north,open=false]",
				"Description": "Fridge - Style 2 Top"
			},
			{
				"char": "O",
				"block": "cfm:cyan_kitchen_counter[facing=south]",
				"Description": "Counter Top - South Facing",
				"Color": "adadadff"
			},
			{
				"char": "8",
				"Description": "Banana Split",
				"blocks": [
					{
						"block": "moa_decor_cookery:tazadecafe",
						"random": 5.0
					},
					{
						"random": 5.0,
						"block": "moa_decor_cookery:taza"
					},
					{
						"random": 150.0,
						"block": "minecraft:air"
					}
				]
			},
			{
				"char": "s",
				"block": "cfm:cyan_kitchen_counter[facing=east]",
				"Description": "Diner Counter - East Facing",
				"Color": "adadadff"
			},
			{
				"char": "E",
				"block": "vm:vending_machine[bottom=true,facing=south]",
				"Description": "Vending Machine - South Facing - Bottom"
			},
			{
				"char": "N",
				"block": "cfm:cyan_kitchen_counter[facing=south]",
				"Description": "Display Counter - White - Bottom"
			},
			{
				"char": "r",
				"block": "cfm:freezer_light[facing=north,open=false]",
				"Description": ""
			},
			{
				"char": "5",
				"block": "vm:vending_machine[bottom=false,facing=south]",
				"Description": ""
			},
			{
				"char": "P",
				"block": "cfm:cyan_kitchen_counter[facing=south]",
				"Description": "Counter Top Corner - South Facing",
				"Color": "adadadff"
			},
			{
				"char": "7",
				"block": "lightmanscurrency:cash_register[facing=south]",
				"Description": ""
			}
		]
	},
	"slices": [
		[
			"#$$#$######$#$$#",
			"$2#############$",
			"$##############$",
			"################",
			"$##############$",
			"$##############$",
			"################",
			"$###############",
			"$###############",
			"################",
			"$##############$",
			"$##############$",
			"################",
			"$##############$",
			"$##############$",
			"#$$#$$####$$#$$#"
		],
		[
			"################",
			"#    erers♴⃕⃕⃕♴#",
			"#        s    ◎#",
			"#             ◎#",
			"#NNNNOOOOP    ◎#",
			"$◍            ◎$",
			" ◍            ◎ ",
			" ◍            ◎ ",
			" ◍            ◎ ",
			" ◍⑮⑰⑫⑪⑰⑫⑪⑰⑫⑪⑰⑫◎ ",
			"$◍            ◎$",
			"#◍            ◎#",
			"#◍⑮⑰⑫⑪⑰⑫⑪⑰⑫⑪⑰⑫◎#",
			"#◍            ◎#",
			"#              #",
			"#####$####$#####"
		],
		[
			"##444######444##",
			"# ◌◌◌ 3 3 ʢ   ʢ#",
			"4             ◎4",
			"4             ◎4",
			"4     ₫ ₫     ◎4",
			"$◍            ◎$",
			" ◍            ◎ ",
			" ◍            ◎ ",
			" ◍            ◎ ",
			" ◍            ◎ ",
			"$◍            ◎$",
			"4◍            ◎4",
			"4◍            ◎4",
			"4◍            ◎4",
			"# ○○○ ○○○○ ○○○ #",
			"##444$4444$444##"
		],
		[
			"##444######444##",
			"# ◌◌◌      ◌◌◌ #",
			"4◍            ◎4",
			"4◍            ◎4",
			"4◍            ◎4",
			"$◍            ◎$",
			" ◍            ◎ ",
			" ◍            ◎ ",
			" ◍            ◎ ",
			" ◍            ◎ ",
			"$◍            ◎$",
			"4◍            ◎4",
			"4◍            ◎4",
			"4◍            ◎4",
			"# ○○○ ○○○○ ○○○ #",
			"##444$4444$444##"
		],
		[
			"##444######444##",
			"# ◌◌◌      ◌◌◌ #",
			"4◍            ◎4",
			"4◍            ◎4",
			"4◍            ◎4",
			"$#            #$",
			" #            # ",
			" #            # ",
			" #            # ",
			" #            # ",
			"$#            #$",
			"4◍            ◎4",
			"4◍            ◎4",
			"4◍            ◎4",
			"# ○○○ ○○○○ ○○○ #",
			"##444$4444$444##"
		],
		[
			"################",
			"################",
			"################",
			"################",
			"################",
			"################",
			"################",
			"################",
			"################",
			"################",
			"################",
			"################",
			"################",
			"################",
			"################",
			"################"
		]
	]
}