{
	"xsize": 16,
	"zsize": 16,
	"Description": "",
	"slices": [
		[
			"#$############$#",
			"$##############$",
			"##2##########2##",
			"################",
			"################",
			"################",
			"################",
			"################",
			"################",
			"################",
			"################",
			"################",
			"################",
			"##2##########2##",
			"$##############$",
			"#$############$#"
		],
		[
			"#$############$#",
			"$              $",
			"#              #",
			"#              #",
			"#              #",
			"#              #",
			"#              #",
			"#              #",
			"#              #",
			"#              #",
			"#              #",
			"#              #",
			"#              #",
			"#              #",
			"$              $",
			"#$############$#"
		],
		[
			"#$############$#",
			"$              $",
			"#              #",
			"#              #",
			"#              #",
			"#              #",
			"#              #",
			"#              #",
			"#              #",
			"#              #",
			"#              #",
			"#              #",
			"#              #",
			"#              #",
			"$              $",
			"#$############$#"
		],
		[
			"#$############$#",
			"$              $",
			"#              #",
			"#              #",
			"#              #",
			"#              #",
			"#              #",
			"#              #",
			"#              #",
			"#              #",
			"#              #",
			"#              #",
			"#              #",
			"#              #",
			"$              $",
			"#$############$#"
		],
		[
			"#$############$#",
			"$              $",
			"#              #",
			"#              #",
			"#              #",
			"#              #",
			"#              #",
			"#              #",
			"#              #",
			"#              #",
			"#              #",
			"#              #",
			"#              #",
			"#              #",
			"$              $",
			"#$############$#"
		],
		[
			"#$############$#",
			"$##############$",
			"################",
			"################",
			"################",
			"################",
			"################",
			"################",
			"################",
			"################",
			"################",
			"################",
			"################",
			"################",
			"$##############$",
			"#$############$#"
		]
	]
}