{
  "xsize": 16,
  "zsize": 16,
  "palette": {
    "palette": [
      {
          "char": "3",
          "block": "literalskyblock:sky_block"
      },
      {
          "char": "4",
          "block": "buildersdelight:glass_5"
      },
      {
          "char": "6",
          "block": "minecraft:torch"
      },
      {
          "char": "7",
          "block": "tanukidecor:gorgeous_lamp"
      },
      {
          "char": "9",
          "block": "simplylight:edge_light_top"
      },
      {
          "char": "I",
          "block": "simplylight:wall_lamp[facing=down]"
      },
      {
          "char": "_",
          "block": "minecraft:glass_bottle"
      },
      {
          "char": "N",
          "block": "mcwroofs:white_attic_roof[facing=west]"
      },
      {
          "char": "O",
          "block": "mcwroofs:white_attic_roof[facing=south]"
      },
      {
          "char": "P",
          "block": "mcwroofs:white_attic_roof[facing=east]"
      },
      {
          "char": "Q",
          "block": "mcwroofs:white_attic_roof[facing=north]"
      }
    ]
  },
  "slices": [
    [
      "#$$#$$#$$#$$#$$#",
      "$##############$",
      "$##############$",
      "################",
      "$##############$",
      "$##############$",
      "################",
      "$##############$",
      "$##############$",
      "################",
      "$##############$",
      "$##############$",
      "################",
      "$##############$",
      "$##############$",
      "#$$#$$#$$#$$#$$#"
    ],
    [
      "######    ######",
      "#              #",
      "#              #",
      "#              #",
      "#              #",
      "#              #",
      "                ",
      "                ",
      "                ",
      "                ",
      "#              #",
      "#              #",
      "#              #",
      "#              #",
      "#              #",
      "######    ######"
    ],
    [
      "##444#    #444##",
      "#              #",
      "4              4",
      "4              4",
      "4              4",
      "#              #",
      "                ",
      "                ",
      "                ",
      "                ",
      "#              #",
      "4              4",
      "4              4",
      "4              4",
      "#              #",
      "##444#    #444##"
    ],
    [
      "##444#    #444##",
      "#              #",
      "4              4",
      "4              4",
      "4              4",
      "#              #",
      "                ",
      "                ",
      "                ",
      "                ",
      "#              #",
      "4              4",
      "4              4",
      "4              4",
      "#              #",
      "##444#    #444##"
    ],
    [
      "################",
      "#99999999999999#",
      "#9            9#",
      "#9            9#",
      "#9            9#",
      "#9            9#",
      "#9            9#",
      "#9            9#",
      "#9            9#",
      "#9            9#",
      "#9            9#",
      "#9            9#",
      "#9            9#",
      "#9            9#",
      "#99999999999999#",
      "################"
    ],
    [
      "################",
      "################",
      "################",
      "################",
      "################",
      "################",
      "################",
      "################",
      "################",
      "################",
      "################",
      "################",
      "################",
      "################",
      "################",
      "################"
    ]
  ]
}