{
	"xsize": 16,
	"zsize": 16,
	"Description": "",
	"palette": {
		"palette": [
			{
				"char": "e",
				"block": "minecraft:gray_concrete",
				"Description": "Concrete Floor",
				"Color": "585858ff"
			}
		]
	},
	"slices": [
		[
			"#$############$#",
			"$eeeeeeeeeeeeee$",
			"#e2eeeeeeeeee2e#",
			"#eeeeeeeeeeeeee#",
			"#eeeeeeeeeeeeee#",
			"#eeeeeeeeeeeeee#",
			"#eeeeeeeeeeeeee#",
			"#eeeeeeeeeeeeee#",
			"#eeeeeeeeeeeeee#",
			"#eeeeeeeeeeeeee#",
			"#eeeeeeeeeeeeee#",
			"#eeeeeeeeeeeeee#",
			"#eeeeeeeeeeeeee#",
			"#e2eeeeeeeeee2e#",
			"$eeeeeeeeeeeeee$",
			"#$############$#"
		],
		[
			"#$#          #$#",
			"$#$          $#$",
			"#$            $#",
			"                ",
			"                ",
			"                ",
			"                ",
			"                ",
			"                ",
			"                ",
			"                ",
			"                ",
			"                ",
			"#$            $#",
			"$#$          $#$",
			"#$#          #$#"
		],
		[
			"#$#          #$#",
			"$#$          $#$",
			"#$            $#",
			"                ",
			"                ",
			"                ",
			"                ",
			"                ",
			"                ",
			"                ",
			"                ",
			"                ",
			"                ",
			"#$            $#",
			"$#$          $#$",
			"#$#          #$#"
		],
		[
			"#$#          #$#",
			"$#$          $#$",
			"#$#          #$#",
			"                ",
			"                ",
			"                ",
			"                ",
			"                ",
			"                ",
			"                ",
			"                ",
			"                ",
			"                ",
			"#$#          #$#",
			"$#$          $#$",
			"#$#          #$#"
		],
		[
			"#$#          #$#",
			"$#$          $#$",
			"#$#          #$#",
			"                ",
			"                ",
			"                ",
			"                ",
			"                ",
			"                ",
			"                ",
			"                ",
			"                ",
			"                ",
			"#$#          #$#",
			"$#$          $#$",
			"#$#          #$#"
		],
		[
			"#$############$#",
			"$##############$",
			"################",
			"################",
			"################",
			"################",
			"################",
			"################",
			"################",
			"################",
			"################",
			"################",
			"################",
			"################",
			"$##############$",
			"#$############$#"
		]
	]
}