{
	"xsize": 16,
	"zsize": 16,
	"Description": "Template For Buildnig 1",
	"palette": {
		"palette": [
			{
				"char": "2",
				"block": "auxiliaryblocks:concrete",
				"Description": "Floor"
			},
			{
				"char": "3",
				"block": "auxiliaryblocks:concrete",
				"Description": "Ceiling"
			}
		]
	},
	"slices": [
		[
			"X$#####$$#####$X",
			"$22222222222222$",
			"#22222222222222#",
			"#22222222222222#",
			"#22222222222222#",
			"#22222222222222#",
			"#22222222222222#",
			"$22222222222222$",
			"$22222222222222$",
			"#22222222222222#",
			"#22222222222222#",
			"#22222222222222#",
			"#22222222222222#",
			"#22222222222222#",
			"$22222222l22222$",
			"X$#####$$#####$X"
		],
		[
			"X#$##########$#X",
			"#333333 3333333#",
			"$3            3$",
			"#3            3#",
			"#3            3#",
			"#3            3#",
			"#3            3#",
			"#              #",
			"#3            3#",
			"#3            3#",
			"#3            3#",
			"#3            3#",
			"#3            3#",
			"$333333 3333333$",
			"#333333  l33333#",
			"X#$##########$#X"
		],
		[
			"X##$########$##X",
			"#333333 3333333#",
			"#3            3#",
			"$3            3$",
			"#3            3#",
			"#3            3#",
			"#3            3#",
			"#              #",
			"#3            3#",
			"#3            3#",
			"#3            3#",
			"#3            3#",
			"$3            3$",
			"#333333 3333333#",
			"#333333  l33333#",
			"X##$########$##X"
		],
		[
			"X###$######$###X",
			"#33333333333333#",
			"#3            3#",
			"#3            3#",
			"$3            3$",
			"#3            3#",
			"#3            3#",
			"#3            3#",
			"#3            3#",
			"#3            3#",
			"#3            3#",
			"$3            3$",
			"#3            3#",
			"#33333333333333#",
			"#33333333l33333#",
			"X###$######$###X"
		],
		[
			"X####$####$####X",
			"#33333333333333#",
			"#3            3#",
			"#3            3#",
			"#3            3#",
			"$3            3$",
			"#3            3#",
			"#3            3#",
			"#3            3#",
			"#3            3#",
			"$3            3$",
			"#3            3#",
			"#3            3#",
			"#33333333333333#",
			"#33333333l33333#",
			"X####$####$####X"
		],
		[
			"X#####$##$#####X",
			"#33333333333333#",
			"#33333333333333#",
			"#33333333333333#",
			"#33333333333333#",
			"#33333333333333#",
			"$33333333333333$",
			"#33333333333333#",
			"#33333333333333#",
			"$33333333333333$",
			"#33333333333333#",
			"#33333333333333#",
			"#33333333333333#",
			"#33333333333333#",
			"#33333333l33333#",
			"X##############X"
		]
	]
}