{
	"xsize": 16,
	"zsize": 16,
	"Description": "",
	"palette": {
		"palette": [
			{
				"char": "3",
				"block": "minecraft:stone",
				"Description": "",
				"Color": "888585ff"
			},
			{
				"char": "☢",
				"Description": "Lantern",
				"blocks": [
					{
						"block": "minecraft:lantern",
						"random": 25
					},
					{
						"block": "buildersdelight:lantern_3",
						"random": 25
					},
					{
						"random": 25,
						"block": "chipped:special_soul_lantern_3"
					},
					{
						"random": 25,
						"block": "chipped:lantern_6"
					},
					{
						"random": 300,
						"block": "buildersdelight:lantern_4"
					}
				]
			}
		]
	},
	"slices": [
		[
			"#$############$#",
			"$##############$",
			"##2##########2##",
			"################",
			"################",
			"################",
			"################",
			"################",
			"################",
			"################",
			"################",
			"################",
			"################",
			"##2##########2##",
			"$##############$",
			"#$############$#"
		],
		[
			"#$############$#",
			"$33333333333333$",
			"#3  3⧒⧒⧒⧒⧒⧒3  3#",
			"#3 ☢3⧑⧑⧑⧑⧑⧑3☢ 3#",
			"#3333⧑3333⧑3333#",
			"#3⧒⧑⧑⧑3⧒⧒3⧑⧑⧑⧒3#",
			"#3⧒⧑333⧒⧒333⧑⧒3#",
			"#3⧒⧑3⧒⧒⧒⧒⧒⧒3⧑⧒3#",
			"#3⧒⧑3⧒⧒⧒⧒⧒⧒3⧑⧒3#",
			"#3⧒⧑333⧒⧒333⧑⧒3#",
			"#3⧒⧑⧑⧑3⧒⧒3⧑⧑⧑⧒3#",
			"#3333⧑3333⧑3333#",
			"#3 ☢3⧑⧑⧑⧑⧑⧑3☢ 3#",
			"#3  3⧒⧒⧒⧒⧒⧒3  3#",
			"$33333333333333$",
			"#$############$#"
		],
		[
			"#$############$#",
			"$33333333333333$",
			"#3  3⧒⧒⧒⧒⧒⧒3  3#",
			"#3  3⧑⧑⧑⧑⧑⧑3  3#",
			"#3333⧑3333⧑3333#",
			"#3⧒⧑⧑⧑3⧒⧒3⧑⧑⧑⧒3#",
			"#3⧒⧑333⧒⧒333⧑⧒3#",
			"#3⧒⧑3⧒⧒⧒⧒⧒⧒3⧑⧒3#",
			"#3⧒⧑3⧒⧒⧒⧒⧒⧒3⧑⧒3#",
			"#3⧒⧑333⧒⧒333⧑⧒3#",
			"#3⧒⧑⧑⧑3⧒⧒3⧑⧑⧑⧒3#",
			"#3333⧑3333⧑3333#",
			"#3  3⧑⧑⧑⧑⧑⧑3  3#",
			"#3  3⧒⧒⧒⧒⧒⧒3  3#",
			"$33333333333333$",
			"#$############$#"
		],
		[
			"#$############$#",
			"$33333333333333$",
			"#3  3⧒⧒⧒⧒⧒⧒3  3#",
			"#3  3⧑⧑⧑⧑⧑⧑3  3#",
			"#3333⧑3333⧑3333#",
			"#3⧒⧑⧑⧑3⧒⧒3⧑⧑⧑⧒3#",
			"#3⧒⧑333⧒⧒333⧑⧒3#",
			"#3⧒⧑3⧒⧒⧒⧒⧒⧒3⧑⧒3#",
			"#3⧒⧑3⧒⧒⧒⧒⧒⧒3⧑⧒3#",
			"#3⧒⧑333⧒⧒333⧑⧒3#",
			"#3⧒⧑⧑⧑3⧒⧒3⧑⧑⧑⧒3#",
			"#3333⧑3333⧑3333#",
			"#3  3⧑⧑⧑⧑⧑⧑3  3#",
			"#3  3⧒⧒⧒⧒⧒⧒3  3#",
			"$33333333333333$",
			"#$############$#"
		],
		[
			"#$############$#",
			"$33333333333333$",
			"#3⧒⧒3⧒⧒⧒⧒⧒⧒3⧒⧒3#",
			"#3⧒⧒3⧑⧑⧑⧑⧑⧑3⧒⧒3#",
			"#3333⧑3333⧑3333#",
			"#3⧒⧑⧑⧑3⧒⧒3⧑⧑⧑⧒3#",
			"#3⧒⧑333⧒⧒333⧑⧒3#",
			"#3⧒⧑3⧒⧒⧒⧒⧒⧒3⧑⧒3#",
			"#3⧒⧑3⧒⧒⧒⧒⧒⧒3⧑⧒3#",
			"#3⧒⧑333⧒⧒333⧑⧒3#",
			"#3⧒⧑⧑⧑3⧒⧒3⧑⧑⧑⧒3#",
			"#3333⧑3333⧑3333#",
			"#3⧒⧒3⧑⧑⧑⧑⧑⧑3⧒⧒3#",
			"#3⧒⧒3⧒⧒⧒⧒⧒⧒3⧒⧒3#",
			"$33333333333333$",
			"#$############$#"
		],
		[
			"#$############$#",
			"$##############$",
			"################",
			"################",
			"################",
			"################",
			"################",
			"################",
			"################",
			"################",
			"################",
			"################",
			"################",
			"################",
			"$##############$",
			"#$############$#"
		]
	]
}