{
	"xsize": 16,
	"zsize": 16,
	"Description": "",
	"palette": {
		"palette": [
			{
				"char": "4",
				"block": "buildersdelight:glass_5",
				"Description": "",
				"Color": "2422aaff"
			},
			{
				"char": "9",
				"block": "simplylight:edge_light_top",
				"Description": ""
			},
			{
				"char": "i",
				"block": "simplylight:edge_light_top[east=false,north=true,south=false,waterlogged=false,west=false]",
				"Description": ""
			},
			{
				"char": "m",
				"block": "simplylight:edge_light_top[east=true,north=false,south=false,waterlogged=false,west=false]",
				"Description": ""
			},
			{
				"char": "k",
				"block": "simplylight:edge_light_top[east=false,north=false,south=false,waterlogged=false,west=true]",
				"Description": ""
			},
			{
				"char": "j",
				"block": "simplylight:edge_light_top[east=true,north=true,south=false,waterlogged=false,west=false]",
				"Description": ""
			},
			{
				"char": "o",
				"block": "simplylight:edge_light_top[east=false,north=false,south=true,waterlogged=false,west=false]",
				"Description": ""
			},
			{
				"char": "n",
				"block": "simplylight:edge_light_top[east=false,north=false,south=true,waterlogged=false,west=true]",
				"Description": ""
			},
			{
				"char": "f",
				"block": "simplylight:edge_light_top[east=false,north=true,south=false,waterlogged=false,west=true]",
				"Description": ""
			},
			{
				"char": "q",
				"block": "simplylight:edge_light_top[east=true,north=false,south=true,waterlogged=false,west=false]",
				"Description": ""
			}
		]
	},
	"slices": [
		[
			"#$$$$$####$$$$$#",
			"$2#############$",
			"$##############$",
			"$##############$",
			"$##############$",
			"$##############$",
			"################",
			"################",
			"################",
			"################",
			"$##############$",
			"$##############$",
			"$##############$",
			"$##############$",
			"$##############$",
			"#$$$$$####$$$$$#"
		],
		[
			"######    #   ##",
			"#         ######",
			"#             # ",
			"#             # ",
			"#             # ",
			"#             ##",
			"                ",
			"                ",
			"                ",
			"                ",
			"##            ##",
			" #            # ",
			" #            # ",
			" #            # ",
			"######    ######",
			"##   #    #   ##"
		],
		[
			"######    #   ##",
			"#         ######",
			"#             # ",
			"#             # ",
			"#             # ",
			"#             ##",
			"                ",
			"                ",
			"                ",
			"                ",
			"##            ##",
			" #            # ",
			" #            # ",
			" #            # ",
			"######    ######",
			"##   #    #   ##"
		],
		[
			"######    #   ##",
			"#         ######",
			"#             # ",
			"#             # ",
			"#             # ",
			"#             ##",
			"                ",
			"                ",
			"                ",
			"                ",
			"##            ##",
			" #            # ",
			" #            # ",
			" #            # ",
			"######    ######",
			"##   #    #   ##"
		],
		[
			"################",
			"#fiiiifiij######",
			"#k        iiij##",
			"#k           m##",
			"#k           m##",
			"#k           m##",
			"#f            j#",
			"#k            m#",
			"#k            m#",
			"#n            q#",
			"##k          m##",
			"##k          m##",
			"##k          m##",
			"##nooo    oooq##",
			"######nooq######",
			"################"
		],
		[
			"################",
			"################",
			"################",
			"################",
			"################",
			"################",
			"################",
			"################",
			"################",
			"################",
			"################",
			"################",
			"################",
			"################",
			"################",
			"################"
		]
	]
}