{
  "xsize": 16,
  "zsize": 16,
  "palette": {
    "palette": [
      {
          "char": "2",
          "block": "chipped:andesite_27"
      },
      {
          "char": "3",
          "block": "chipped:white_wool_4"
      },
      {
          "char": "4",
          "block": "chipped:white_concrete_7"
      },
      {
          "char": "5",
          "block": "davebuildingmod:cut_laboratory_block"
      },
      {
          "char": "6",
          "block": "everycomp:mcd/minestuck/dead_four_panel_door[facing=south,half=lower]"
      },
      {
          "char": "7",
          "block": "everycomp:mcd/minestuck/dead_four_panel_door[facing=south,half=upper]"
      },
      {
          "char": "8",
          "block": "everycomp:mcd/minestuck/dead_four_panel_door[facing=west,half=lower]"
      },
      {
          "char": "9",
          "block": "everycomp:mcd/minestuck/dead_four_panel_door[facing=west,half=upper]"
      },
      {
          "char": "E",
          "block": "everycomp:mcd/minestuck/dead_mystic_door[facing=north,half=lower]"
      },
      {
          "char": "H",
          "block": "everycomp:mcd/minestuck/dead_mystic_door[facing=north,half=upper]"
      },
      {
          "char": "I",
          "block": "everycomp:mcd/minestuck/dead_four_panel_door[facing=east,half=lower]"
      },
      {
          "char": "J",
          "block": "everycomp:mcd/minestuck/dead_four_panel_door[facing=east,half=upper]"
      },
      {
          "char": "M",
          "block": "luphieclutteredmod:luphie_glowing_moon[facing=south]"
      },
      {
          "char": "0",
          "block": "supplementaries:pedestal"
      }
    ]
  },
  "slices": [
    [
      "################",
      "#22222222222222#",
      "#22222222222222#",
      "#22222222222222#",
      "#22222222222222#",
      "#22222222222222#",
      "#22222222222222#",
      "#22222222222222#",
      "#22222222222222#",
      "#22222222222222#",
      "#22222222222222#",
      "#22222222222222#",
      "#22222222222222#",
      "#22222222222222#",
      "#22222222l22222#",
      "################"
    ],
    [
      "################",
      "#554433 3344555#",
      "#554433E3344555#",
      "#33         333#",
      "#33         333#",
      "#44         444#",
      "#44         444#",
      "# 8    0    I ##",
      "#44         444#",
      "#44         444#",
      "#33         333#",
      "#33         333#",
      "#55443363344555#",
      "#554433 3344555#",
      "#554433  l44555#",
      "################"
    ],
    [
      "################",
      "#554433 3344555#",
      "#554433H3344555#",
      "#33    M    333#",
      "#33         333#",
      "#44         444#",
      "#44         444#",
      "# 9         J ##",
      "#44         444#",
      "#44         444#",
      "#33         333#",
      "#33         333#",
      "#55443373344555#",
      "#554433 3344555#",
      "#554433  l44555#",
      "################"
    ],
    [
      "################",
      "#55334434433555#",
      "#55334434433555#",
      "#44         444#",
      "#44         444#",
      "#33         333#",
      "#33         333#",
      "#44         444#",
      "#33         333#",
      "#33         333#",
      "#44         444#",
      "#44         444#",
      "#55334434433555#",
      "#55334434433555#",
      "#55334434l33555#",
      "################"
    ],
    [
      "################",
      "#55334434433555#",
      "#55334434433555#",
      "#44         444#",
      "#44         444#",
      "#33         333#",
      "#33         333#",
      "#44         444#",
      "#33         333#",
      "#33         333#",
      "#44         444#",
      "#44         444#",
      "#55334434433555#",
      "#55334434433555#",
      "#55334434l33555#",
      "################"
    ],
    [
      "################",
      "#22222222222222#",
      "#22222222222222#",
      "#22222222222222#",
      "#22222222222222#",
      "#22222222222222#",
      "#22222222222222#",
      "#22222222222222#",
      "#22222222222222#",
      "#22222222222222#",
      "#22222222222222#",
      "#22222222222222#",
      "#22222222222222#",
      "#22222222222222#",
      "#22222222l22222#",
      "################"
    ]
  ]
}