{
	"xsize": 16,
	"zsize": 16,
	"Description": "",
	"palette": {
		"palette": [
			{
				"char": "2",
				"block": "auxiliaryblocks:concrete",
				"Description": "",
				"Color": "553e1fff"
			},
			{
				"char": "3",
				"block": "chipped:blue_concrete_5",
				"Description": ""
			},
			{
				"char": "4",
				"block": "chipped:blue_concrete_14",
				"Description": ""
			},
			{
				"char": "5",
				"block": "chipped:blue_concrete_11",
				"Description": ""
			},
			{
				"char": "6",
				"block": "chipped:blue_concrete_13",
				"Description": ""
			},
			{
				"char": "7",
				"block": "chipped:blue_concrete_16",
				"Description": ""
			},
			{
				"char": "8",
				"block": "auxiliaryblocks:light_blue_frameless_glass",
				"Description": ""
			},
			{
				"char": "9",
				"block": "simplylight:wall_lamp[facing=down,waterlogged=true]",
				"Description": ""
			},
			{
				"char": "E",
				"block": "chipped:blue_concrete_15",
				"Description": ""
			},
			{
				"char": "H",
				"block": "everycomp:cfm/ecologics/walnut_crate",
				"Description": ""
			},
			{
				"char": "I",
				"block": "mcwdoors:metal_windowed_door[facing=south,half=lower]",
				"Description": ""
			},
			{
				"char": "J",
				"block": "mcwdoors:metal_windowed_door[facing=south,half=upper]",
				"Description": ""
			},
			{
				"char": "M",
				"blocks": [
					{
						"random": 85.0,
						"block": "moa_decor_cookery:barrilcerrado"
					},
					{
						"random": 80.0,
						"block": "moa_decor_cookery:barrilcerrado"
					}
				],
				"Description": ""
			},
			{
				"char": "N",
				"block": "mcwdoors:metal_windowed_door[facing=east,half=lower]",
				"Description": ""
			},
			{
				"char": "O",
				"block": "mcwdoors:metal_windowed_door[facing=east,half=upper]",
				"Description": ""
			},
			{
				"char": "P",
				"block": "mcwdoors:metal_windowed_door[facing=west,half=lower]",
				"Description": ""
			},
			{
				"char": "Q",
				"block": "mcwdoors:metal_windowed_door[facing=west,half=upper]",
				"Description": ""
			}
		]
	},
	"slices": [
		[
			"################",
			"#22222222222222#",
			"#22222222222222#",
			"#22222222222222#",
			"#22222222222222#",
			"#22222222222222#",
			"#22222222222222#",
			"#22222222222222#",
			"#22222222222222#",
			"#22222222222222#",
			"#22222222222222#",
			"#22222222222222#",
			"#22222222222222#",
			"#22222222222222#",
			"#22222222l22222#",
			"################"
		],
		[
			"################",
			"#33333333333333#",
			"#33333333333333#",
			"#33333333333333#",
			"#34543454345433#",
			"#7           77#",
			"#3           33#",
			"#P           N #",
			"#3          ƚ33#",
			"#7          ņ77#",
			"#345543 3455433#",
			"#333333 3333333#",
			"#333333 3333333#",
			"#333333I3333333#",
			"#333333  l33333#",
			"################"
		],
		[
			"################",
			"#3WWWWWWWWWWW33#",
			"#3WWWWWWWWWWW33#",
			"#3WWWWWWWWWWW33#",
			"#38888888888833#",
			"#7           77#",
			"#3           33#",
			"#Q           O #",
			"#3           33#",
			"#7           77#",
			"#388883 3888833#",
			"#3WWWW8 8WWWWW3#",
			"#3WWWW8 8WWWWW3#",
			"#333333J3333333#",
			"#333333  l33333#",
			"################"
		],
		[
			"################",
			"#3WWWWWWWWWWW33#",
			"#3WWWWWWWWWWW33#",
			"#3WWWWWWWWWWW33#",
			"#38888888888833#",
			"#7           77#",
			"#3           33#",
			"#E           EE#",
			"#3           33#",
			"#7           77#",
			"#388883 3888833#",
			"#3WWWW8 8WWWWW3#",
			"#3WWWW8 8WWWWW3#",
			"#333333 3333333#",
			"#333333E3l33333#",
			"################"
		],
		[
			"################",
			"#3WWWWWWWWWWW33#",
			"#3W9WWW9WWW9W33#",
			"#3WWWWWWWWWWW33#",
			"#38888888888833#",
			"#7           77#",
			"#3           33#",
			"#E           EE#",
			"#3           33#",
			"#7           77#",
			"#388883E3888833#",
			"#3W99W8 8W99W33#",
			"#3WWWW8 8WWWW33#",
			"#333333 3333333#",
			"#333333E3l33333#",
			"################"
		],
		[
			"################",
			"#33333333333333#",
			"#33333333333333#",
			"#33333333333333#",
			"#34643464346433#",
			"#3           33#",
			"#3           33#",
			"#3           33#",
			"#3           33#",
			"#3           33#",
			"#34664333466433#",
			"#33333333333333#",
			"#33333333333333#",
			"#33333333333333#",
			"#33333333l33333#",
			"################"
		]
	]
}